2025-06-05 15:06:00,995 ERROR scheduler Exception in Enqueue Events for Site nps.local
Traceback (most recent call last):
  File "/home/nikhilsrivatsa/demo/apps/frappe/frappe/utils/scheduler.py", line 117, in enqueue_events_for_site
    if is_scheduler_inactive():
  File "/home/nikhilsrivatsa/demo/apps/frappe/frappe/utils/scheduler.py", line 161, in is_scheduler_inactive
    if is_scheduler_disabled(verbose=verbose):
  File "/home/nikhilsrivatsa/demo/apps/frappe/frappe/utils/scheduler.py", line 174, in is_scheduler_disabled
    frappe.db.get_single_value("System Settings", "enable_scheduler")
  File "/home/nikhilsrivatsa/demo/apps/frappe/frappe/database/database.py", line 886, in get_single_value
    ).run()
  File "/home/nikhilsrivatsa/demo/apps/frappe/frappe/query_builder/utils.py", line 85, in execute_query
    result = frappe.local.db.sql(query, params, *args, **kwargs)  # nosemgrep
  File "/home/nikhilsrivatsa/demo/apps/frappe/frappe/database/database.py", line 239, in sql
    self.connect()
  File "/home/nikhilsrivatsa/demo/apps/frappe/frappe/database/database.py", line 137, in connect
    self.get_connection()
  File "/home/nikhilsrivatsa/demo/apps/frappe/frappe/database/mariadb/database.py", line 106, in get_connection
    conn = self._get_connection()
  File "/home/nikhilsrivatsa/demo/apps/frappe/frappe/database/mariadb/database.py", line 112, in _get_connection
    return self.create_connection()
  File "/home/nikhilsrivatsa/demo/apps/frappe/frappe/database/mariadb/database.py", line 115, in create_connection
    return pymysql.connect(**self.get_connection_settings())
  File "/home/nikhilsrivatsa/demo/env/lib/python3.10/site-packages/pymysql/connections.py", line 361, in __init__
    self.connect()
  File "/home/nikhilsrivatsa/demo/env/lib/python3.10/site-packages/pymysql/connections.py", line 669, in connect
    self._request_authentication()
  File "/home/nikhilsrivatsa/demo/env/lib/python3.10/site-packages/pymysql/connections.py", line 957, in _request_authentication
    auth_packet = self._read_packet()
  File "/home/nikhilsrivatsa/demo/env/lib/python3.10/site-packages/pymysql/connections.py", line 775, in _read_packet
    packet.raise_for_error()
  File "/home/nikhilsrivatsa/demo/env/lib/python3.10/site-packages/pymysql/protocol.py", line 219, in raise_for_error
    err.raise_mysql_exception(self._data)
  File "/home/nikhilsrivatsa/demo/env/lib/python3.10/site-packages/pymysql/err.py", line 150, in raise_mysql_exception
    raise errorclass(errno, errval)
pymysql.err.OperationalError: (1045, "Access denied for user '_25b19bc873a47f56'@'localhost' (using password: YES)")
2025-06-05 15:10:00,091 ERROR scheduler Exception in Enqueue Events for Site nps.local
Traceback (most recent call last):
  File "/home/nikhilsrivatsa/demo/apps/frappe/frappe/utils/scheduler.py", line 117, in enqueue_events_for_site
    if is_scheduler_inactive():
  File "/home/nikhilsrivatsa/demo/apps/frappe/frappe/utils/scheduler.py", line 161, in is_scheduler_inactive
    if is_scheduler_disabled(verbose=verbose):
  File "/home/nikhilsrivatsa/demo/apps/frappe/frappe/utils/scheduler.py", line 174, in is_scheduler_disabled
    frappe.db.get_single_value("System Settings", "enable_scheduler")
  File "/home/nikhilsrivatsa/demo/apps/frappe/frappe/database/database.py", line 886, in get_single_value
    ).run()
  File "/home/nikhilsrivatsa/demo/apps/frappe/frappe/query_builder/utils.py", line 85, in execute_query
    result = frappe.local.db.sql(query, params, *args, **kwargs)  # nosemgrep
  File "/home/nikhilsrivatsa/demo/apps/frappe/frappe/database/database.py", line 239, in sql
    self.connect()
  File "/home/nikhilsrivatsa/demo/apps/frappe/frappe/database/database.py", line 137, in connect
    self.get_connection()
  File "/home/nikhilsrivatsa/demo/apps/frappe/frappe/database/mariadb/database.py", line 106, in get_connection
    conn = self._get_connection()
  File "/home/nikhilsrivatsa/demo/apps/frappe/frappe/database/mariadb/database.py", line 112, in _get_connection
    return self.create_connection()
  File "/home/nikhilsrivatsa/demo/apps/frappe/frappe/database/mariadb/database.py", line 115, in create_connection
    return pymysql.connect(**self.get_connection_settings())
  File "/home/nikhilsrivatsa/demo/env/lib/python3.10/site-packages/pymysql/connections.py", line 361, in __init__
    self.connect()
  File "/home/nikhilsrivatsa/demo/env/lib/python3.10/site-packages/pymysql/connections.py", line 669, in connect
    self._request_authentication()
  File "/home/nikhilsrivatsa/demo/env/lib/python3.10/site-packages/pymysql/connections.py", line 957, in _request_authentication
    auth_packet = self._read_packet()
  File "/home/nikhilsrivatsa/demo/env/lib/python3.10/site-packages/pymysql/connections.py", line 775, in _read_packet
    packet.raise_for_error()
  File "/home/nikhilsrivatsa/demo/env/lib/python3.10/site-packages/pymysql/protocol.py", line 219, in raise_for_error
    err.raise_mysql_exception(self._data)
  File "/home/nikhilsrivatsa/demo/env/lib/python3.10/site-packages/pymysql/err.py", line 150, in raise_mysql_exception
    raise errorclass(errno, errval)
pymysql.err.OperationalError: (1698, "Access denied for user '_25b19bc873a47f56'@'localhost'")
2025-06-05 15:14:00,800 ERROR scheduler Exception in Enqueue Events for Site nps.local
Traceback (most recent call last):
  File "/home/nikhilsrivatsa/demo/apps/frappe/frappe/utils/scheduler.py", line 117, in enqueue_events_for_site
    if is_scheduler_inactive():
  File "/home/nikhilsrivatsa/demo/apps/frappe/frappe/utils/scheduler.py", line 161, in is_scheduler_inactive
    if is_scheduler_disabled(verbose=verbose):
  File "/home/nikhilsrivatsa/demo/apps/frappe/frappe/utils/scheduler.py", line 174, in is_scheduler_disabled
    frappe.db.get_single_value("System Settings", "enable_scheduler")
  File "/home/nikhilsrivatsa/demo/apps/frappe/frappe/database/database.py", line 886, in get_single_value
    ).run()
  File "/home/nikhilsrivatsa/demo/apps/frappe/frappe/query_builder/utils.py", line 85, in execute_query
    result = frappe.local.db.sql(query, params, *args, **kwargs)  # nosemgrep
  File "/home/nikhilsrivatsa/demo/apps/frappe/frappe/database/database.py", line 239, in sql
    self.connect()
  File "/home/nikhilsrivatsa/demo/apps/frappe/frappe/database/database.py", line 137, in connect
    self.get_connection()
  File "/home/nikhilsrivatsa/demo/apps/frappe/frappe/database/mariadb/database.py", line 106, in get_connection
    conn = self._get_connection()
  File "/home/nikhilsrivatsa/demo/apps/frappe/frappe/database/mariadb/database.py", line 112, in _get_connection
    return self.create_connection()
  File "/home/nikhilsrivatsa/demo/apps/frappe/frappe/database/mariadb/database.py", line 115, in create_connection
    return pymysql.connect(**self.get_connection_settings())
  File "/home/nikhilsrivatsa/demo/env/lib/python3.10/site-packages/pymysql/connections.py", line 361, in __init__
    self.connect()
  File "/home/nikhilsrivatsa/demo/env/lib/python3.10/site-packages/pymysql/connections.py", line 669, in connect
    self._request_authentication()
  File "/home/nikhilsrivatsa/demo/env/lib/python3.10/site-packages/pymysql/connections.py", line 957, in _request_authentication
    auth_packet = self._read_packet()
  File "/home/nikhilsrivatsa/demo/env/lib/python3.10/site-packages/pymysql/connections.py", line 775, in _read_packet
    packet.raise_for_error()
  File "/home/nikhilsrivatsa/demo/env/lib/python3.10/site-packages/pymysql/protocol.py", line 219, in raise_for_error
    err.raise_mysql_exception(self._data)
  File "/home/nikhilsrivatsa/demo/env/lib/python3.10/site-packages/pymysql/err.py", line 150, in raise_mysql_exception
    raise errorclass(errno, errval)
pymysql.err.OperationalError: (1698, "Access denied for user '_25b19bc873a47f56'@'localhost'")
2025-06-10 11:50:00,886 ERROR scheduler Exception in Enqueue Events for Site NPS.local
Traceback (most recent call last):
  File "/home/nikhilsrivatsa/demo/env/lib/python3.10/site-packages/redis/connection.py", line 1536, in get_connection
    if connection.can_read() and self.cache is None:
  File "/home/nikhilsrivatsa/demo/env/lib/python3.10/site-packages/redis/connection.py", line 622, in can_read
    return self._parser.can_read(timeout)
  File "/home/nikhilsrivatsa/demo/env/lib/python3.10/site-packages/redis/_parsers/base.py", line 140, in can_read
    return self._buffer and self._buffer.can_read(timeout)
  File "/home/nikhilsrivatsa/demo/env/lib/python3.10/site-packages/redis/_parsers/socket.py", line 95, in can_read
    return bool(self.unread_bytes()) or self._read_from_socket(
  File "/home/nikhilsrivatsa/demo/env/lib/python3.10/site-packages/redis/_parsers/socket.py", line 68, in _read_from_socket
    raise ConnectionError(SERVER_CLOSED_CONNECTION_ERROR)
redis.exceptions.ConnectionError: Connection closed by server.

During handling of the above exception, another exception occurred:

Traceback (most recent call last):
  File "/home/nikhilsrivatsa/demo/env/lib/python3.10/site-packages/redis/connection.py", line 385, in connect_check_health
    sock = self.retry.call_with_retry(
  File "/home/nikhilsrivatsa/demo/env/lib/python3.10/site-packages/redis/retry.py", line 87, in call_with_retry
    return do()
  File "/home/nikhilsrivatsa/demo/env/lib/python3.10/site-packages/redis/connection.py", line 386, in <lambda>
    lambda: self._connect(), lambda error: self.disconnect(error)
  File "/home/nikhilsrivatsa/demo/env/lib/python3.10/site-packages/redis/connection.py", line 797, in _connect
    raise err
  File "/home/nikhilsrivatsa/demo/env/lib/python3.10/site-packages/redis/connection.py", line 781, in _connect
    sock.connect(socket_address)
ConnectionRefusedError: [Errno 111] Connection refused

During handling of the above exception, another exception occurred:

Traceback (most recent call last):
  File "/home/nikhilsrivatsa/demo/apps/frappe/frappe/utils/scheduler.py", line 120, in enqueue_events_for_site
    enqueue_events()
  File "/home/nikhilsrivatsa/demo/apps/frappe/frappe/utils/scheduler.py", line 140, in enqueue_events
    if job_type.enqueue():
  File "/home/nikhilsrivatsa/demo/apps/frappe/frappe/core/doctype/scheduled_job_type/scheduled_job_type.py", line 71, in enqueue
    if not self.is_job_in_queue():
  File "/home/nikhilsrivatsa/demo/apps/frappe/frappe/core/doctype/scheduled_job_type/scheduled_job_type.py", line 93, in is_job_in_queue
    return is_job_enqueued(self.rq_job_id)
  File "/home/nikhilsrivatsa/demo/apps/frappe/frappe/utils/background_jobs.py", line 663, in is_job_enqueued
    return get_job_status(job_id) in (JobStatus.QUEUED, JobStatus.STARTED)
  File "/home/nikhilsrivatsa/demo/apps/frappe/frappe/utils/background_jobs.py", line 668, in get_job_status
    if job := get_job(job_id):
  File "/home/nikhilsrivatsa/demo/apps/frappe/frappe/utils/background_jobs.py", line 674, in get_job
    return Job.fetch(create_job_id(job_id), connection=get_redis_conn())
  File "/home/nikhilsrivatsa/demo/env/lib/python3.10/site-packages/rq/job.py", line 670, in fetch
    job.refresh()
  File "/home/nikhilsrivatsa/demo/env/lib/python3.10/site-packages/rq/job.py", line 1033, in refresh
    data = self.connection.hgetall(self.key)
  File "/home/nikhilsrivatsa/demo/env/lib/python3.10/site-packages/redis/commands/core.py", line 4959, in hgetall
    return self.execute_command("HGETALL", name, keys=[name])
  File "/home/nikhilsrivatsa/demo/env/lib/python3.10/site-packages/redis/client.py", line 623, in execute_command
    return self._execute_command(*args, **options)
  File "/home/nikhilsrivatsa/demo/env/lib/python3.10/site-packages/redis/client.py", line 629, in _execute_command
    conn = self.connection or pool.get_connection()
  File "/home/nikhilsrivatsa/demo/env/lib/python3.10/site-packages/redis/utils.py", line 191, in wrapper
    return func(*args, **kwargs)
  File "/home/nikhilsrivatsa/demo/env/lib/python3.10/site-packages/redis/connection.py", line 1540, in get_connection
    connection.connect()
  File "/home/nikhilsrivatsa/demo/env/lib/python3.10/site-packages/redis/connection.py", line 379, in connect
    self.connect_check_health(check_health=True)
  File "/home/nikhilsrivatsa/demo/env/lib/python3.10/site-packages/redis/connection.py", line 391, in connect_check_health
    raise ConnectionError(self._error_message(e))
redis.exceptions.ConnectionError: Error 111 connecting to 127.0.0.1:11000. Connection refused.
2025-06-10 11:50:01,026 ERROR scheduler Exception in Enqueue Events for Site demo.local
Traceback (most recent call last):
  File "/home/nikhilsrivatsa/demo/env/lib/python3.10/site-packages/redis/connection.py", line 385, in connect_check_health
    sock = self.retry.call_with_retry(
  File "/home/nikhilsrivatsa/demo/env/lib/python3.10/site-packages/redis/retry.py", line 87, in call_with_retry
    return do()
  File "/home/nikhilsrivatsa/demo/env/lib/python3.10/site-packages/redis/connection.py", line 386, in <lambda>
    lambda: self._connect(), lambda error: self.disconnect(error)
  File "/home/nikhilsrivatsa/demo/env/lib/python3.10/site-packages/redis/connection.py", line 797, in _connect
    raise err
  File "/home/nikhilsrivatsa/demo/env/lib/python3.10/site-packages/redis/connection.py", line 781, in _connect
    sock.connect(socket_address)
ConnectionRefusedError: [Errno 111] Connection refused

During handling of the above exception, another exception occurred:

Traceback (most recent call last):
  File "/home/nikhilsrivatsa/demo/apps/frappe/frappe/utils/scheduler.py", line 120, in enqueue_events_for_site
    enqueue_events()
  File "/home/nikhilsrivatsa/demo/apps/frappe/frappe/utils/scheduler.py", line 140, in enqueue_events
    if job_type.enqueue():
  File "/home/nikhilsrivatsa/demo/apps/frappe/frappe/core/doctype/scheduled_job_type/scheduled_job_type.py", line 71, in enqueue
    if not self.is_job_in_queue():
  File "/home/nikhilsrivatsa/demo/apps/frappe/frappe/core/doctype/scheduled_job_type/scheduled_job_type.py", line 93, in is_job_in_queue
    return is_job_enqueued(self.rq_job_id)
  File "/home/nikhilsrivatsa/demo/apps/frappe/frappe/utils/background_jobs.py", line 663, in is_job_enqueued
    return get_job_status(job_id) in (JobStatus.QUEUED, JobStatus.STARTED)
  File "/home/nikhilsrivatsa/demo/apps/frappe/frappe/utils/background_jobs.py", line 668, in get_job_status
    if job := get_job(job_id):
  File "/home/nikhilsrivatsa/demo/apps/frappe/frappe/utils/background_jobs.py", line 674, in get_job
    return Job.fetch(create_job_id(job_id), connection=get_redis_conn())
  File "/home/nikhilsrivatsa/demo/env/lib/python3.10/site-packages/rq/job.py", line 670, in fetch
    job.refresh()
  File "/home/nikhilsrivatsa/demo/env/lib/python3.10/site-packages/rq/job.py", line 1033, in refresh
    data = self.connection.hgetall(self.key)
  File "/home/nikhilsrivatsa/demo/env/lib/python3.10/site-packages/redis/commands/core.py", line 4959, in hgetall
    return self.execute_command("HGETALL", name, keys=[name])
  File "/home/nikhilsrivatsa/demo/env/lib/python3.10/site-packages/redis/client.py", line 623, in execute_command
    return self._execute_command(*args, **options)
  File "/home/nikhilsrivatsa/demo/env/lib/python3.10/site-packages/redis/client.py", line 629, in _execute_command
    conn = self.connection or pool.get_connection()
  File "/home/nikhilsrivatsa/demo/env/lib/python3.10/site-packages/redis/utils.py", line 191, in wrapper
    return func(*args, **kwargs)
  File "/home/nikhilsrivatsa/demo/env/lib/python3.10/site-packages/redis/connection.py", line 1530, in get_connection
    connection.connect()
  File "/home/nikhilsrivatsa/demo/env/lib/python3.10/site-packages/redis/connection.py", line 379, in connect
    self.connect_check_health(check_health=True)
  File "/home/nikhilsrivatsa/demo/env/lib/python3.10/site-packages/redis/connection.py", line 391, in connect_check_health
    raise ConnectionError(self._error_message(e))
redis.exceptions.ConnectionError: Error 111 connecting to 127.0.0.1:11000. Connection refused.
